
2022-08-20 16:24:20,459 INFO: errors [in C:\Users\Ebimo\Desktop\silver-eureka\app.py:547]
2022-08-20 16:24:37,461 ERROR: Exception on /venues [GET] [in C:\Users\Ebimo\AppData\Local\Programs\Python\Python310\lib\site-packages\flask\app.py:1457]
Traceback (most recent call last):
  File "C:\Users\Ebimo\AppData\Local\Programs\Python\Python310\lib\site-packages\sqlalchemy\engine\base.py", line 1819, in _execute_context
    self.dialect.do_execute(
  File "C:\Users\Ebimo\AppData\Local\Programs\Python\Python310\lib\site-packages\sqlalchemy\engine\default.py", line 732, in do_execute
    cursor.execute(statement, parameters)
sqlite3.OperationalError: no such table: venue

The above exception was the direct cause of the following exception:

Traceback (most recent call last):
  File "C:\Users\Ebimo\AppData\Local\Programs\Python\Python310\lib\site-packages\flask\app.py", line 2073, in wsgi_app
    response = self.full_dispatch_request()
  File "C:\Users\Ebimo\AppData\Local\Programs\Python\Python310\lib\site-packages\flask\app.py", line 1518, in full_dispatch_request
    rv = self.handle_user_exception(e)
  File "C:\Users\Ebimo\AppData\Local\Programs\Python\Python310\lib\site-packages\flask\app.py", line 1516, in full_dispatch_request
    rv = self.dispatch_request()
  File "C:\Users\Ebimo\AppData\Local\Programs\Python\Python310\lib\site-packages\flask\app.py", line 1502, in dispatch_request
    return self.ensure_sync(self.view_functions[rule.endpoint])(**req.view_args)
  File "C:\Users\Ebimo\Desktop\silver-eureka\app.py", line 115, in venues
    Ven = Venue.query.distinct(Venue.city, Venue.state).all()
  File "C:\Users\Ebimo\AppData\Local\Programs\Python\Python310\lib\site-packages\sqlalchemy\orm\query.py", line 2768, in all
    return self._iter().all()
  File "C:\Users\Ebimo\AppData\Local\Programs\Python\Python310\lib\site-packages\sqlalchemy\orm\query.py", line 2903, in _iter
    result = self.session.execute(
  File "C:\Users\Ebimo\AppData\Local\Programs\Python\Python310\lib\site-packages\sqlalchemy\orm\session.py", line 1712, in execute
    result = conn._execute_20(statement, params or {}, execution_options)
  File "C:\Users\Ebimo\AppData\Local\Programs\Python\Python310\lib\site-packages\sqlalchemy\engine\base.py", line 1631, in _execute_20
    return meth(self, args_10style, kwargs_10style, execution_options)
  File "C:\Users\Ebimo\AppData\Local\Programs\Python\Python310\lib\site-packages\sqlalchemy\sql\elements.py", line 332, in _execute_on_connection
    return connection._execute_clauseelement(
  File "C:\Users\Ebimo\AppData\Local\Programs\Python\Python310\lib\site-packages\sqlalchemy\engine\base.py", line 1498, in _execute_clauseelement
    ret = self._execute_context(
  File "C:\Users\Ebimo\AppData\Local\Programs\Python\Python310\lib\site-packages\sqlalchemy\engine\base.py", line 1862, in _execute_context
    self._handle_dbapi_exception(
  File "C:\Users\Ebimo\AppData\Local\Programs\Python\Python310\lib\site-packages\sqlalchemy\engine\base.py", line 2043, in _handle_dbapi_exception
    util.raise_(
  File "C:\Users\Ebimo\AppData\Local\Programs\Python\Python310\lib\site-packages\sqlalchemy\util\compat.py", line 208, in raise_
    raise exception
  File "C:\Users\Ebimo\AppData\Local\Programs\Python\Python310\lib\site-packages\sqlalchemy\engine\base.py", line 1819, in _execute_context
    self.dialect.do_execute(
  File "C:\Users\Ebimo\AppData\Local\Programs\Python\Python310\lib\site-packages\sqlalchemy\engine\default.py", line 732, in do_execute
    cursor.execute(statement, parameters)
sqlalchemy.exc.OperationalError: (sqlite3.OperationalError) no such table: venue
[SQL: SELECT DISTINCT venue.id AS venue_id, venue.name AS venue_name, venue.genres AS venue_genres, venue.address AS venue_address, venue.city AS venue_city, venue.state AS venue_state, venue.phone AS venue_phone, venue.website_link AS venue_website_link, venue.facebook_link AS venue_facebook_link, venue.seeking_talent AS venue_seeking_talent, venue.seeking_description AS venue_seeking_description, venue.image_link AS venue_image_link 
FROM venue]
(Background on this error at: https://sqlalche.me/e/14/e3q8)
